<robot name="yahboomcar_X3plus">
    <link name="base_footprint"/>
    <link name="imu_link"/>
    <link name="base_link">
        <inertial>
            <origin xyz="-0.0304416859098744 4.23384368655101E-05 0.0448234503408059" rpy="0 0 0"/>
            <mass value="1.0754239466482"/>
            <inertia
                    ixx="0.0208831789264125"
                    ixy="2.4618093127858E-06"
                    ixz="0.00616019290028669"
                    iyy="0.0265621377486244"
                    iyz="-1.10079499865282E-06"
                    izz="0.0129535610833954"/>
        </inertial>
        <visual>
            <origin xyz="0 0 0" rpy="0 0 0"/>
            <geometry>
                <mesh filename="package://yahboomcar_description/meshes/X3plus/visual/base_link.STL"/>
            </geometry>
            <material name="">
                <color rgba="0 0.7 0 1"/>
            </material>
        </visual>
        <collision>
            <origin xyz="0 0 0" rpy="0 0 0"/>
            <geometry>
                <mesh filename="package://yahboomcar_description/meshes/X3plus/collision/base_link.STL"/>
            </geometry>
        </collision>
    </link>
    <joint name="base_joint" type="fixed">
        <parent link="base_footprint"/>
        <child link="base_link"/>
        <origin xyz="0.0 0.0 0.076" rpy="0 0 0"/>
    </joint>
    <joint name="base_imu" type="fixed">
        <parent link="base_link"/>
        <child link="imu_link"/>
        <origin xyz="0.001 0.017 0.0322" rpy="0 3.1415 1.5707"/>
    </joint>
    <link name="camera_link">
        <inertial>
            <origin xyz="-0.00227617338844674 -6.0192031420306E-06 -0.00616567843043764" rpy="0 0 0"/>
            <mass value="0.224346273348015"/>
            <inertia
                    ixx="0.000420259753235012"
                    ixy="2.65423313072081E-08"
                    ixz="-9.20335513714662E-06"
                    iyy="7.89049803518943E-05"
                    iyz="6.08195761013683E-09"
                    izz="0.000414416844201259"/>
        </inertial>
        <visual>
            <origin xyz="0 0 0" rpy="0 0 0"/>
            <geometry>
                <mesh filename="package://yahboomcar_description/meshes/sensor/visual/camera_link.STL"/>
            </geometry>
            <material name="">
                <color rgba="0.7 0.7 0.7 1"/>
            </material>
        </visual>
        <collision>
            <origin xyz="0 0 0" rpy="0 0 0"/>
            <geometry>
                <mesh filename="package://yahboomcar_description/meshes/sensor/collision/camera_link.STL"/>
            </geometry>
        </collision>
    </link>
    <joint name="astra_joint" type="fixed">
        <origin xyz="-0.043645 0 0.41955" rpy="0 0 0"/>
        <parent link="base_link"/>
        <child link="camera_link"/>
    </joint>
    <link name="laser_link">
        <inertial>
            <origin xyz="-0.0193193958962378 0.000338302570666659 -0.01482422577972" rpy="0 0 0"/>
            <mass value="0.0433399617554554"/>
            <inertia
                    ixx="2.03361882296905E-05"
                    ixy="-3.29493708697467E-07"
                    ixz="-9.00810512916648E-06"
                    iyy="4.37540022779682E-05"
                    iyz="-2.16320544253691E-07"
                    izz="4.81888233320734E-05"/>
        </inertial>
        <visual>
            <origin xyz="0 0 0" rpy="0 0 0"/>
            <geometry>
                <mesh filename="package://yahboomcar_description/meshes/sensor/visual/laser_link.STL"/>
            </geometry>
            <material name="">
                <color rgba="0.7 0.7 0.7 1"/>
            </material>
        </visual>
        <collision>
            <origin xyz="0 0 0" rpy="0 0 0"/>
            <geometry>
                <mesh filename="package://yahboomcar_description/meshes/sensor/collision/laser_link.STL"/>
            </geometry>
        </collision>
    </link>
    <joint name="laser_joint" type="fixed">
        <origin xyz="0.10478 0 0.0471" rpy="0 0 0"/>
        <parent link="base_link"/>
        <child link="laser_link"/>
    </joint>

    <link name="arm_link1">
        <inertial>
            <origin xyz="1.99179507982521E-05 -5.98354652829568E-05 0.0114289358828097" rpy="0 0 0"/>
            <mass value="0.0279545499871709"/>
            <inertia
                    ixx="1.19144359314975E-05"
                    ixy="-9.26068510046816E-09"
                    ixz="3.16060516198683E-09"
                    iyy="1.05642517915377E-05"
                    iyz="2.69674403668579E-08"
                    izz="1.49639510661413E-05"/>
        </inertial>
        <visual>
            <origin xyz="0 0 0" rpy="0 0 0"/>
            <geometry>
                <mesh filename="package://yahboomcar_description/meshes/X3plus/visual/arm_link1.STL"/>
            </geometry>
            <material name="">
                <color rgba="0.7 0.7 0.7 1"/>
            </material>
        </visual>
        <collision>
            <origin xyz="0 0 0" rpy="0 0 0"/>
            <geometry>
                <mesh filename="package://yahboomcar_description/meshes/X3plus/collision/arm_link1.STL"/>
            </geometry>
        </collision>
    </link>
    <joint name="arm_joint1" type="revolute">
        <origin xyz="0.09825 0 0.102" rpy="0 0 0"/>
        <parent link="base_link"/>
        <child link="arm_link1"/>
        <axis xyz="0 0 -1"/>
        <limit lower="-1.5708" upper="1.5708" effort="100" velocity="1"/>
    </joint>
    <link name="arm_link2">
        <inertial>
            <origin xyz="0.024903 -0.0022632 -0.00066663" rpy="0 0 0"/>
            <mass value="0.031605"/>
            <inertia
                    ixx="5.8495E-06"
                    ixy="-8.8092E-07"
                    ixz="1.5336E-07"
                    iyy="2.667E-05"
                    iyz="7.1365E-09"
                    izz="2.4695E-05"/>
        </inertial>
        <visual>
            <origin xyz="0 0 0" rpy="0 0 0"/>
            <geometry>
                <mesh filename="package://yahboomcar_description/meshes/X3plus/visual/arm_link2.STL"/>
            </geometry>
            <material name="">
                <color rgba="0 0.7 0 1"/>
            </material>
        </visual>
        <collision>
            <origin xyz="0 0 0" rpy="0 0 0"/>
            <geometry>
                <mesh filename="package://yahboomcar_description/meshes/X3plus/collision/arm_link2.STL"/>
            </geometry>
        </collision>
    </link>
    <joint name="arm_joint2" type="revolute">
        <origin xyz="0 0 0.0405" rpy="-1.5708 0 0"/>
        <parent link="arm_link1"/>
        <child link="arm_link2"/>
        <axis xyz="0 0 -1"/>
        <limit lower="-1.5708" upper="1.5708" effort="100" velocity="1"/>
    </joint>
    <link name="arm_link3">
        <inertial>
            <origin xyz="0.024903 -0.0022634 -0.0013962" rpy="0 0 0"/>
            <mass value="0.031605"/>
            <inertia
                    ixx="5.8492E-06"
                    ixy="-8.8063E-07"
                    ixz="1.4331E-07"
                    iyy="2.667E-05"
                    iyz="8.9675E-09"
                    izz="2.4695E-05"/>
        </inertial>
        <visual>
            <origin xyz="0 0 0" rpy="0 0 0"/>
            <geometry>
                <mesh filename="package://yahboomcar_description/meshes/X3plus/visual/arm_link3.STL"/>
            </geometry>
            <material name="">
                <color rgba="0.7 0.7 0.7 1"/>
            </material>
        </visual>
        <collision>
            <origin xyz="0 0 0" rpy="0 0 0"/>
            <geometry>
                <mesh filename="package://yahboomcar_description/meshes/X3plus/collision/arm_link3.STL"/>
            </geometry>
        </collision>
    </link>
    <joint name="arm_joint3" type="revolute">
        <origin xyz="0 -0.0829 0" rpy="0 0 0"/>
        <parent link="arm_link2"/>
        <child link="arm_link3"/>
        <axis xyz="0 0 -1"/>
        <limit lower="-1.5708" upper="1.5708" effort="100" velocity="1"/>
    </joint>
    <link name="arm_link4">
        <inertial>
            <origin xyz="0.036246 0.0023413 -0.0019655" rpy="0 0 0"/>
            <mass value="0.049766"/>
            <inertia
                    ixx="1.1857E-05"
                    ixy="-6.5371E-06"
                    ixz="-4.1044E-08"
                    iyy="3.6323E-05"
                    iyz="-1.2132E-07"
                    izz="4.1769E-05"/>
        </inertial>
        <visual>
            <origin xyz="0 0 0" rpy="0 0 0"/>
            <geometry>
                <mesh filename="package://yahboomcar_description/meshes/X3plus/visual/arm_link4.STL"/>
            </geometry>
            <material name="">
                <color rgba="0 0.7 0 1"/>
            </material>
        </visual>
        <collision>
            <origin xyz="0 0 0" rpy="0 0 0"/>
            <geometry>
                <mesh filename="package://yahboomcar_description/meshes/X3plus/collision/arm_link4.STL"/>
            </geometry>
        </collision>
    </link>
    <joint name="arm_joint4" type="revolute">
        <origin xyz="0 -0.0829 0" rpy="0 0 0"/>
        <parent link="arm_link3"/>
        <child link="arm_link4"/>
        <axis xyz="0 0 -1"/>
        <limit lower="-1.5708" upper="1.5708" effort="100" velocity="1"/>
    </joint>
    <link name="arm_link5">
        <inertial>
            <origin xyz="0.0023228 0.018169 0.028684" rpy="0 0 0"/>
            <mass value="0.04069"/>
            <inertia
                    ixx="1.0627E-05"
                    ixy="-3.0402E-07"
                    ixz="-1.9524E-07"
                    iyy="9.6306E-06"
                    iyz="-1.3265E-06"
                    izz="1.3298E-05"/>
        </inertial>
        <visual>
            <origin xyz="0 0 0" rpy="0 0 0"/>
            <geometry>
                <mesh filename="package://yahboomcar_description/meshes/X3plus/visual/arm_link5.STL"/>
            </geometry>
            <material name="">
                <color rgba="0.7 0.7 0.7 1"/>
            </material>
        </visual>
        <collision>
            <origin xyz="0 0 0" rpy="0 0 0"/>
            <geometry>
                <mesh filename="package://yahboomcar_description/meshes/X3plus/collision/arm_link5.STL"/>
            </geometry>
        </collision>
    </link>
    <joint name="arm_joint5" type="revolute">
        <origin xyz="-0.00215 -0.17455 0" rpy="1.5708 0 0"/>
        <parent link="arm_link4"/>
        <child link="arm_link5"/>
        <axis xyz="0 0 1"/>
        <limit lower="-1.5708" upper="3.14159" effort="100" velocity="1"/>
    </joint>

    <link name="rlink1">
        <inertial>
            <origin xyz="0.00653227489887718 0.000416767821288678 0.000980984132845697" rpy="0 0 0"/>
            <mass value="0.00117883201961805"/>
            <inertia
                    ixx="3.30415008842026E-08"
                    ixy="8.05114594599862E-09"
                    ixz="-1.46441757999184E-10"
                    iyy="1.67254031134004E-07"
                    iyz="-9.31932225400159E-12"
                    izz="1.99277285249309E-07"/>
        </inertial>
        <visual>
            <origin xyz="0 0 0" rpy="0 0 0"/>
            <geometry>
                <mesh filename="package://yahboomcar_description/meshes/X3plus/visual/rlink1.STL"/>
            </geometry>
            <material name="">
                <color rgba="0 0.7 0 1"/>
            </material>
        </visual>
        <collision>
            <origin xyz="0 0 0" rpy="0 0 0"/>
            <geometry>
                <mesh filename="package://yahboomcar_description/meshes/X3plus/visual/rlink1.STL"/>
            </geometry>
        </collision>
    </link>
    <joint name="grip_joint" type="revolute">
        <origin xyz="-0.0035 -0.012625 -0.0685" rpy="0 -1.5708 0"/>
        <parent link="arm_link5"/>
        <child link="rlink1"/>
        <axis xyz="0 0 1"/>
        <limit lower="-1.54" upper="0" effort="100" velocity="1"/>
    </joint>
    <link name="rlink2">
        <inertial>
            <origin xyz="0.021158 0.0063295 -0.0030251" rpy="0 0 0"/>
            <mass value="0.0024469"/>
            <inertia
                    ixx="5.188E-08"
                    ixy="-1.2303E-07"
                    ixz="-1.2978E-09"
                    iyy="6.3204E-07"
                    iyz="-3.8824E-10"
                    izz="6.6364E-07"/>
        </inertial>
        <visual>
            <origin xyz="0 0 0" rpy="0 0 0"/>
            <geometry>
                <mesh filename="package://yahboomcar_description/meshes/X3plus/visual/rlink2.STL"/>
            </geometry>
            <material name="">
                <color rgba="0 0.7 0 1"/>
            </material>
        </visual>
        <collision>
            <origin xyz="0 0 0" rpy="0 0 0"/>
            <geometry>
                <mesh filename="package://yahboomcar_description/meshes/X3plus/visual/rlink2.STL"/>
            </geometry>
        </collision>
    </link>
    <joint name="rlink_joint2" type="continuous">
        <origin xyz="0.03 -0.00075429 0" rpy="0 0 0"/>
        <parent link="rlink1"/>
        <child link="rlink2"/>
        <axis xyz="0 0 1"/>
        <mimic joint="grip_joint" multiplier="-1"/>
    </joint>
    <link name="rlink3">
        <inertial>
            <origin xyz="0.014355 1.1499E-05 -0.0033992" rpy="0 0 0"/>
            <mass value="0.00087627"/>
            <inertia
                    ixx="2.0534E-08"
                    ixy="-1.0235E-10"
                    ixz="1.074E-09"
                    iyy="1.4825E-07"
                    iyz="8.7073E-13"
                    izz="1.3089E-07"/>
        </inertial>
        <visual>
            <origin xyz="0 0 0" rpy="0 0 0"/>
            <geometry>
                <mesh filename="package://yahboomcar_description/meshes/X3plus/visual/rlink3.STL"/>
            </geometry>
            <material name="">
                <color rgba="0 0.7 0 1"/>
            </material>
        </visual>
        <collision>
            <origin xyz="0 0 0" rpy="0 0 0"/>
            <geometry>
                <mesh filename="package://yahboomcar_description/meshes/X3plus/visual/rlink3.STL"/>
            </geometry>
        </collision>
    </link>
    <joint name="rlink_joint3" type="continuous">
        <origin xyz="-0.0035 -0.0045 -0.0505" rpy="0 -1.5708 0"/>
        <parent link="arm_link5"/>
        <child link="rlink3"/>
        <axis xyz="0 0 1"/>
        <mimic joint="grip_joint" multiplier="1"/>
    </joint>
    <link name="llink1">
        <inertial>
            <origin xyz="0.00628617364795481 -0.000318530407893543 0.00100000338924466" rpy="0 0 0"/>
            <mass value="0.00121010771282268"/>
            <inertia
                    ixx="3.18226609060835E-08"
                    ixy="-8.06236004452728E-09"
                    ixz="3.99064856025629E-14"
                    iyy="1.69267681405915E-07"
                    iyz="1.87039773440675E-14"
                    izz="2.00283878176223E-07"/>
        </inertial>
        <visual>
            <origin xyz="0 0 0" rpy="0 0 0"/>
            <geometry>
                <mesh filename="package://yahboomcar_description/meshes/X3plus/visual/llink1.STL"/>
            </geometry>
            <material name="">
                <color rgba="0 0.7 0 1"/>
            </material>
        </visual>
        <collision>
            <origin xyz="0 0 0" rpy="0 0 0"/>
            <geometry>
                <mesh filename="package://yahboomcar_description/meshes/X3plus/visual/llink1.STL"/>
            </geometry>
        </collision>
    </link>
    <joint name="llink_joint1" type="continuous">
        <origin xyz="-0.0035 0.012375 -0.0685" rpy="0 -1.5708 0"/>
        <parent link="arm_link5"/>
        <child link="llink1"/>
        <axis xyz="0 0 1"/>
        <mimic joint="grip_joint" multiplier="-1"/>
    </joint>
    <link name="llink2">
        <inertial>
            <origin xyz="0.021159 -0.0063248 -0.0030251" rpy="0 0 0"/>
            <mass value="0.0024469"/>
            <inertia ixx="5.1826E-08" ixy="1.229E-07" ixz="-1.2979E-09" iyy="6.321E-07" iyz="3.8796E-10"
                     izz="6.6364E-07"/>
        </inertial>
        <visual>
            <origin xyz="0 0 0" rpy="0 0 0"/>
            <geometry>
                <mesh filename="package://yahboomcar_description/meshes/X3plus/visual/llink2.STL"/>
            </geometry>
            <material name="">
                <color rgba="0 0.7 0 1"/>
            </material>
        </visual>
        <collision>
            <origin xyz="0 0 0" rpy="0 0 0"/>
            <geometry>
                <mesh filename="package://yahboomcar_description/meshes/X3plus/visual/llink2.STL"/>
            </geometry>
        </collision>
    </link>
    <joint name="llink_joint2" type="continuous">
        <origin xyz="0.03 0.00065104 0" rpy="0 0 0"/>
        <parent link="llink1"/>
        <child link="llink2"/>
        <axis xyz="0 0 1"/>
        <mimic joint="grip_joint" multiplier="1"/>
    </joint>
    <link name="llink3">
        <inertial>
            <origin xyz="0.014354 -7.4795E-05 -0.0033992" rpy="0 0 0"/>
            <mass value="0.00087627"/>
            <inertia ixx="2.0537E-08" ixy="6.6549E-10" ixz="1.074E-09" iyy="1.4825E-07" iyz="-5.5867E-12"
                     izz="1.3089E-07"/>
        </inertial>
        <visual>
            <origin xyz="0 0 0" rpy="0 0 0"/>
            <geometry>
                <mesh filename="package://yahboomcar_description/meshes/X3plus/visual/llink3.STL"/>
            </geometry>
            <material name="">
                <color rgba="0 0.7 0 1"/>
            </material>
        </visual>
        <collision>
            <origin xyz="0 0 0" rpy="0 0 0"/>
            <geometry>
                <mesh filename="package://yahboomcar_description/meshes/X3plus/visual/llink3.STL"/>
            </geometry>
        </collision>
    </link>
    <joint name="llink_joint3" type="continuous">
        <origin xyz="-0.0035 0.0045 -0.0505" rpy="0 -1.5708 0"/>
        <parent link="arm_link5"/>
        <child link="llink3"/>
        <axis xyz="0 0 1"/>
        <mimic joint="grip_joint" multiplier="-1"/>
    </joint>

    <link name="mono_link">
        <inertial>
            <origin xyz="5.8458E-05 0.0095015 -0.0014824" rpy="0 0 0"/>
            <mass value="0.0097589"/>
            <inertia ixx="3.3488E-06" ixy="1.3667E-08" ixz="6.4235E-09" iyy="1.8662E-06" iyz="-1.0265E-07"
                     izz="2.5696E-06"/>
        </inertial>
        <visual>
            <origin xyz="0 0 0" rpy="0 0 0"/>
            <geometry>
                <mesh filename="package://yahboomcar_description/meshes/sensor/visual/mono_link.STL"/>
            </geometry>
            <material name="">
                <color rgba="0.7 0.7 0.7 1"/>
            </material>
        </visual>
        <collision>
            <origin xyz="0 0 0" rpy="0 0 0"/>
            <geometry>
                <mesh filename="package://yahboomcar_description/meshes/sensor/collision/mono_link.STL"/>
            </geometry>
        </collision>
    </link>
    <joint name="mono_joint" type="fixed">
        <origin xyz="-0.0481 -0.05145 -0.0022" rpy="1.5708 0 0"/>
        <parent link="arm_link4"/>
        <child link="mono_link"/>
    </joint>
</robot>